<?xml version="1.0" ?>
<!-- =================================================================================== -->
<!-- |    This document was autogenerated by xacro from pioneer3dx.xacro               | -->
<!-- |    EDITING THIS FILE BY HAND IS NOT RECOMMENDED                                 | -->
<!-- =================================================================================== -->
<robot name="pioneer3dx">
  <material name="black">
    <color rgba="0.0 0.0 0.0 1.0"/>
  </material>
  <material name="blue">
    <color rgba="0.0 0.0 0.8 1.0"/>
  </material>
  <material name="green">
    <color rgba="0.0 0.8 0.0 1.0"/>
  </material>
  <material name="grey">
    <color rgba="0.2 0.2 0.2 1.0"/>
  </material>
  <material name="orange">
    <color rgba="1.0 0.4235294117647059 0.0392156862745098 1.0"/>
  </material>
  <material name="brown">
    <color rgba="0.8705882352941177 0.8117647058823529 0.7647058823529411 1.0"/>
  </material>
  <material name="red">
    <color rgba="0.8 0.0 0.0 1.0"/>
  </material>
  <material name="white">
    <color rgba="1.0 1.0 1.0 1.0"/>
  </material>
  <!-- see https://secure.wikimedia.org/wikipedia/en/wiki/List_of_moment_of_inertia_tensors -->
  <gazebo>
    <plugin filename="libgazebo_ros_control.so" name="gazebo_ros_control">
      <robotNamespace>p3dx</robotNamespace>
      <legacyModeNS>true</legacyModeNS>
    </plugin>
  </gazebo>
  <gazebo>
    <plugin filename="libgazebo_ros_joint_state_publisher.so" name="joint_state_publisher">
      <robotNamespace>p3dx</robotNamespace>
      <jointName>chassis_swivel_joint, swivel_wheel_joint, left_hub_joint, right_hub_joint</jointName>
      <updateRate>10.0</updateRate>
      <alwaysOn>true</alwaysOn>
    </plugin>
  </gazebo>
  <!-- ground truth -->
  <gazebo>
    <plugin filename="libgazebo_ros_p3d.so" name="p3d_base_controller">
      <alwaysOn>true</alwaysOn>
      <updateRate>50.0</updateRate>
      <bodyName>base_link</bodyName>
      <topicName>base_pose_ground_truth</topicName>
      <gaussianNoise>0.01</gaussianNoise>
      <frameName>map</frameName>
      <!-- initialize odometry for fake localization -->
      <xyzOffsets>0 0 0</xyzOffsets>
      <rpyOffsets>0 0 0</rpyOffsets>
    </plugin>
  </gazebo>
  <!-- base_link -->
  <link name="base_link"/>
  <!-- Chassis -->
  <joint name="base_link_chassis_joint" type="fixed">
    <origin rpy="0 0 0" xyz="0 0 0"/>
    <parent link="base_link"/>
    <child link="chassis"/>
  </joint>
  <link name="chassis">
    <visual name="chassis_visual">
      <origin rpy="0 0 0" xyz="-0.045 0 0.148"/>
      <geometry name="pioneer_geom">
        <mesh filename="package://p3dx_description/meshes/p3dx/chassis.stl"/>
      </geometry>
      <material name="ChassisRed">
        <color rgba="0.851 0.0 0.0 1.0"/>
      </material>
    </visual>
    <collision>
      <origin rpy="0 0 0" xyz="-0.045 0 0.148"/>
      <geometry>
        <mesh filename="package://p3dx_description/meshes/p3dx/chassis.stl"/>
      </geometry>
    </collision>
    <inertial>
      <mass value="9.0"/>
      <origin xyz="0 0 0"/>
      <inertia ixx="0.07499997000000001" ixy="0.0" ixz="0.0" iyy="0.12149995139999999" iyz="0.0" izz="0.14789994084"/>
    </inertial>
  </link>
  <gazebo reference="chassis">
    <material value="Gazebo/Red"/>
  </gazebo>
  <!-- Top -->
  <joint name="chassis_top_joint" type="fixed">
    <origin rpy="0 0 0" xyz="-0.045 0 0.234"/>
    <parent link="chassis"/>
    <child link="top"/>
  </joint>
  <link name="top">
    <visual>
      <origin rpy="0 0 0" xyz="0 0 0"/>
      <geometry name="top_geom">
        <mesh filename="package://p3dx_description/meshes/p3dx/top.stl"/>
      </geometry>
      <material name="TopBlack">
        <color rgba="0.038 0.038 0.038 1.0"/>
      </material>
    </visual>
    <collision>
      <origin rpy="0 0 0" xyz="0.0 0 0.0"/>
      <geometry>
        <mesh filename="package://p3dx_description/meshes/p3dx/top.stl"/>
      </geometry>
    </collision>
    <inertial>
      <mass value="1.0"/>
      <origin xyz="0 0 0"/>
      <inertia ixx="0.01204166185" ixy="0.0" ixz="0.0" iyy="0.016510410062499998" iyz="0.0" izz="0.028535405252499996"/>
    </inertial>
  </link>
  <gazebo reference="top">
    <material value="Gazebo/Black"/>
  </gazebo>
  <!-- Front Sonar -->
  <joint name="chassis_sonar_joint" type="fixed">
    <origin rpy="0 0 0" xyz="0.109 0 0.209"/>
    <parent link="chassis"/>
    <child link="sonar"/>
  </joint>
  <link name="sonar">
    <inertial>
      <mass value="0.0001"/>
      <origin xyz="0 0 0"/>
      <inertia ixx="1" ixy="0" ixz="0" iyy="1" iyz="0" izz="1"/>
    </inertial>
    <!--<visual name="front_sonar_vis">-->
    <visual>
      <origin rpy="0 0 0" xyz="0 0 0"/>
      <geometry name="pioneer_geom">
        <mesh filename="package://p3dx_description/meshes/p3dx/back_sonar.stl"/>
      </geometry>
      <material name="SonarYellow">
        <color rgba="0.715 0.583 0.210 1.0"/>
      </material>
    </visual>
    <collision>
      <origin rpy="0 0 0" xyz="0 0 0"/>
      <geometry>
        <box size="0.01 0.01 0.01"/>
      </geometry>
    </collision>
  </link>
  <gazebo reference="sonar">
    <material value="Gazebo/Yellow"/>
  </gazebo>
  <joint name="chassis_battery0_joint" type="fixed">
    <origin rpy="0 0 0" xyz="-0.14 0.0 0.13"/>
    <parent link="chassis"/>
    <child link="battery0"/>
  </joint>
  <link name="battery0">
    <visual name="battery0_visual">
      <origin rpy="0 0 0" xyz="0 0 0"/>
      <geometry name="battery0_geometry">
        <box size="0.151 0.065 0.094"/>
      </geometry>
      <material name="battery0_material">
        <color rgba="0.038 0.038 0.038 1.0"/>
      </material>
    </visual>
    <inertial>
      <mass value="2.5"/>
      <origin xyz="0 0 0"/>
      <inertia ixx="0.0035208319250000005" ixy="0.0" ixz="0.0" iyy="0.007604163625000001" iyz="0.0" izz="0.004083331700000001"/>
    </inertial>
  </link>
  <gazebo reference="battery0">
    <material value="Gazebo/Black"/>
  </gazebo>
  <!-- Hubcap -->
  <joint name="right_hub_joint" type="continuous">
    <origin rpy="0 0 0" xyz="0 -0.15 0.09"/>
    <parent link="chassis"/>
    <child link="right_hub"/>
    <axis xyz="0 1 0"/>
  </joint>
  <link name="right_hub">
    <inertial>
      <mass value="0.01"/>
      <origin xyz="0 0 0"/>
      <inertia ixx="0.012411765597" ixy="0" ixz="0" iyy="0.015218160428" iyz="0" izz="0.011763977943"/>
    </inertial>
    <!--<visual name="base_visual">-->
    <visual>
      <origin rpy="0 0 0" xyz="0 0 0"/>
      <geometry name="pioneer_geom">
        <mesh filename="package://p3dx_description/meshes/p3dx/right_hubcap.stl"/>
      </geometry>
      <material name="HubcapYellow">
        <color rgba="1.0 0.811 0.151 1.0"/>
      </material>
    </visual>
    <collision>
      <origin rpy="0 0 0" xyz="0 0 0"/>
      <geometry>
        <box size="0.0001 0.0001 0.0001"/>
      </geometry>
    </collision>
  </link>
  <gazebo reference="right_hub">
    <material value="Gazebo/Yellow"/>
  </gazebo>
  <!-- Wheel -->
  <joint name="right_wheel_joint" type="fixed">
    <axis xyz="0 1 0"/>
    <origin rpy="0 0 0" xyz="0 0 0"/>
    <parent link="right_hub"/>
    <child link="right_wheel"/>
  </joint>
  <link name="right_wheel">
    <inertial>
      <mass value="0.5"/>
      <origin xyz="0 0 0"/>
      <inertia ixx="0.012411765597" ixy="0" ixz="0" iyy="0.015218160428" iyz="0" izz="0.011763977943"/>
    </inertial>
    <!--<visual name="base_visual">-->
    <visual>
      <origin rpy="0 0 0" xyz="0 0 0"/>
      <geometry name="pioneer_geom">
        <mesh filename="package://p3dx_description/meshes/p3dx/right_wheel.stl"/>
      </geometry>
      <material name="WheelBlack">
        <color rgba="0.117 0.117 0.117 1"/>
      </material>
    </visual>
    <collision>
      <origin rpy="-1.57079635 0 0" xyz="0 0 0"/>
      <geometry>
        <!--<mesh filename="${meshes}/${side}_wheel.stl"/>-->
        <cylinder length="0.01" radius="0.09"/>
      </geometry>
    </collision>
  </link>
  <gazebo reference="right_wheel">
    <material value="Gazebo/Black"/>
  </gazebo>
  <transmission name="right_wheel_trans" type="SimpleTransmission">
    <type>transmission_interface/SimpleTransmission</type>
    <actuator name="right_wheel_motor">
      <mechanicalReduction>1</mechanicalReduction>
    </actuator>
    <joint name="right_hub_joint">
      <hardwareInterface>hardware_interface/VelocityJointInterface</hardwareInterface>
    </joint>
  </transmission>
  <!-- Hubcap -->
  <joint name="left_hub_joint" type="continuous">
    <origin rpy="0 0 0" xyz="0 0.15 0.09"/>
    <parent link="chassis"/>
    <child link="left_hub"/>
    <axis xyz="0 1 0"/>
  </joint>
  <link name="left_hub">
    <inertial>
      <mass value="0.01"/>
      <origin xyz="0 0 0"/>
      <inertia ixx="0.012411765597" ixy="0" ixz="0" iyy="0.015218160428" iyz="0" izz="0.011763977943"/>
    </inertial>
    <!--<visual name="base_visual">-->
    <visual>
      <origin rpy="0 0 0" xyz="0 0 0"/>
      <geometry name="pioneer_geom">
        <mesh filename="package://p3dx_description/meshes/p3dx/left_hubcap.stl"/>
      </geometry>
      <material name="HubcapYellow">
        <color rgba="1.0 0.811 0.151 1.0"/>
      </material>
    </visual>
    <collision>
      <origin rpy="0 0 0" xyz="0 0 0"/>
      <geometry>
        <box size="0.0001 0.0001 0.0001"/>
      </geometry>
    </collision>
  </link>
  <gazebo reference="left_hub">
    <material value="Gazebo/Yellow"/>
  </gazebo>
  <!-- Wheel -->
  <joint name="left_wheel_joint" type="fixed">
    <axis xyz="0 1 0"/>
    <origin rpy="0 0 0" xyz="0 0 0"/>
    <parent link="left_hub"/>
    <child link="left_wheel"/>
  </joint>
  <link name="left_wheel">
    <inertial>
      <mass value="0.5"/>
      <origin xyz="0 0 0"/>
      <inertia ixx="0.012411765597" ixy="0" ixz="0" iyy="0.015218160428" iyz="0" izz="0.011763977943"/>
    </inertial>
    <!--<visual name="base_visual">-->
    <visual>
      <origin rpy="0 0 0" xyz="0 0 0"/>
      <geometry name="pioneer_geom">
        <mesh filename="package://p3dx_description/meshes/p3dx/left_wheel.stl"/>
      </geometry>
      <material name="WheelBlack">
        <color rgba="0.117 0.117 0.117 1"/>
      </material>
    </visual>
    <collision>
      <origin rpy="-1.57079635 0 0" xyz="0 0 0"/>
      <geometry>
        <!--<mesh filename="${meshes}/${side}_wheel.stl"/>-->
        <cylinder length="0.01" radius="0.09"/>
      </geometry>
    </collision>
  </link>
  <gazebo reference="left_wheel">
    <material value="Gazebo/Black"/>
  </gazebo>
  <transmission name="left_wheel_trans" type="SimpleTransmission">
    <type>transmission_interface/SimpleTransmission</type>
    <actuator name="left_wheel_motor">
      <mechanicalReduction>1</mechanicalReduction>
    </actuator>
    <joint name="left_hub_joint">
      <hardwareInterface>hardware_interface/VelocityJointInterface</hardwareInterface>
    </joint>
  </transmission>
  <!-- Swivel -->
  <joint name="chassis_swivel_joint" type="continuous">
    <origin rpy="0 0 0" xyz="-0.185 0 0.055"/>
    <axis xyz="0 0 1"/>
    <anchor xyz="0 0 0"/>
    <limit effort="100" k_velocity="0" velocity="100"/>
    <joint_properties damping="0.0" friction="0.0"/>
    <parent link="chassis"/>
    <child link="swivel"/>
  </joint>
  <link name="swivel">
    <inertial>
      <mass value="0.1"/>
      <origin xyz="0 0 0"/>
      <inertia ixx="0.01" ixy="0" ixz="0" iyy="0.01" iyz="0" izz="0.01"/>
    </inertial>
    <!--<visual name="base_visual">-->
    <visual>
      <origin rpy="0 0 0" xyz="0 0 0"/>
      <geometry name="pioneer_geom">
        <mesh filename="package://p3dx_description/meshes/p3dx/swivel.stl"/>
      </geometry>
      <material name="swivel">
        <color rgba="0.5 0.5 0.5 1"/>
      </material>
    </visual>
    <collision>
      <origin rpy="0 0 0" xyz="0 0 0"/>
      <geometry>
        <box size="0.01 0.01 0.01"/>
      </geometry>
    </collision>
  </link>
  <gazebo reference="swivel">
    <material value="Gazebo/Grey"/>
  </gazebo>
  <!-- Center Wheel -->
  <joint name="swivel_wheel_joint" type="continuous">
    <origin rpy="0 0 0" xyz="-0.026 0 -0.016"/>
    <axis xyz="0 1 0"/>
    <anchor xyz="0 0 0"/>
    <limit effort="100" k_velocity="0" velocity="100"/>
    <joint_properties damping="0.0" friction="0.0"/>
    <parent link="swivel"/>
    <child link="center_wheel"/>
  </joint>
  <link name="center_wheel">
    <inertial>
      <mass value="0.1"/>
      <origin xyz="0 0 0"/>
      <inertia ixx="0.012411765597" ixy="-0.000711733678" ixz="0.00050272983" iyy="0.015218160428" iyz="-0.000004273467" izz="0.011763977943"/>
    </inertial>
    <!--<visual name="base_visual">-->
    <visual>
      <origin rpy="0 0 0" xyz="0 0 0"/>
      <geometry name="pioneer_geom">
        <mesh filename="package://p3dx_description/meshes/p3dx/center_wheel.stl"/>
      </geometry>
      <material name="WheelBlack">
        <color rgba="0.117 0.117 0.117 1"/>
      </material>
    </visual>
    <collision>
      <origin rpy="-1.57079635 0 0" xyz="0 0 0"/>
      <geometry>
        <!--<mesh filename="${meshes}/center_wheel.stl"/>-->
        <cylinder length="0.01" radius="0.0375"/>
      </geometry>
    </collision>
  </link>
  <gazebo reference="center_wheel">
    <material value="Gazebo/Black"/>
  </gazebo>
  <!-- Center Hubcap -->
  <joint name="wheel_hubcap_joint" type="fixed">
    <origin rpy="0 0 0" xyz="-0.0035 0 -0.001"/>
    <parent link="center_wheel"/>
    <child link="center_hubcap"/>
  </joint>
  <link name="center_hubcap">
    <inertial>
      <mass value="0.01"/>
      <origin xyz="0 0 0"/>
      <inertia ixx="0.012411765597" ixy="-0.000711733678" ixz="0.00050272983" iyy="0.015218160428" iyz="-0.000004273467" izz="0.011763977943"/>
    </inertial>
    <!--<visual name="base_visual">-->
    <visual>
      <origin rpy="0 0 0" xyz="0 0 0"/>
      <geometry name="pioneer_geom">
        <mesh filename="package://p3dx_description/meshes/p3dx/center_hubcap.stl"/>
      </geometry>
      <material name="swivel">
        <color rgba="0.5 0.5 0.5 1"/>
      </material>
    </visual>
    <collision>
      <origin rpy="0 0 0" xyz="0 0 0"/>
      <geometry>
        <box size="0.01 0.01 0.01"/>
      </geometry>
    </collision>
  </link>
  <gazebo reference="center_hubcap">
    <material value="Gazebo/Grey"/>
  </gazebo>
  <joint name="hokuyo_utm30lx_base_joint" type="fixed">
    <!-- FRONT MOUNT  -->
    <!-- origin xyz="0.29 0 0.1" -->
    <!-- TOP MOUNT -->
    <!-- origin xyz="0.0 0.0 0.325"-->
    <origin rpy="0 0 0" xyz="0.12 0 0.23"/>
    <parent link="chassis"/>
    <child link="hokuyo_utm30lx_base_link"/>
  </joint>
  <link name="hokuyo_utm30lx_base_link">
    <visual>
      <origin rpy="0 0 0" xyz="0 0 0.055"/>
      <geometry>
        <mesh filename="package://p3dx_description/meshes/sensors/hokuyo_utm_30lx.dae"/>
      </geometry>
    </visual>
    <inertial>
      <mass value="1e-5"/>
      <origin rpy="0 0 0" xyz="0 0 0"/>
      <inertia ixx="1e-6" ixy="0" ixz="0" iyy="1e-6" iyz="0" izz="1e-6"/>
    </inertial>
  </link>
  <link name="hokuyo_utm30lx_link">
    </link>
  <joint name="hokuyo_utm30lx_joint" type="fixed">
    <parent link="hokuyo_utm30lx_base_link"/>
    <child link="hokuyo_utm30lx_link"/>
    <origin rpy="0 0 0" xyz="0.00 0 0.055"/>
  </joint>
  <gazebo reference="hokuyo_utm30lx_link">
    <sensor name="hokuyo_utm30lx_sensor" type="ray">
      <pose>0 0 0 0 0 0</pose>
      <visualize>false</visualize>
      <update_rate>30</update_rate>
      <ray>
        <scan>
          <horizontal>
            <samples>1081</samples>
            <resolution>1</resolution>
            <min_angle>-2.356194490192345</min_angle>
            <max_angle>2.356194490192345</max_angle>
          </horizontal>
        </scan>
        <range>
          <min>0.10</min>
          <max>30.0</max>
          <resolution>0.01</resolution>
        </range>
        <noise>
          <type>gaussian</type>
          <mean>0.0</mean>
          <stddev>0.001</stddev>
        </noise>
      </ray>
      <plugin filename="libgazebo_ros_laser.so" name="hokuyo_utm30lx_controller">
        <topicName>/scan</topicName>
        <frameName>/hokuyo_utm30lx_link</frameName>
      </plugin>
    </sensor>
  </gazebo>
</robot>

